2024-02-02 02:40:22 | ERROR | Object of type User is not JSON serializable
2024-02-02 02:40:22 | ERROR | Traceback (most recent call last):
  File "C:\Users\pc\Documents\Desarrollo\flask-folders-structure-master\src\routes\UserRoute.py", line 35, in find
    "response": jsonify(User(*response))}
                ^^^^^^^^^^^^^^^^^^^^^^^^
  File "C:\Users\pc\Documents\Desarrollo\flask-folders-structure-master\venv\Lib\site-packages\flask\json\__init__.py", line 170, in jsonify
    return current_app.json.response(*args, **kwargs)
           ^^^^^^^^^^^^^^^^^^^^^^^^^^^^^^^^^^^^^^^^^^
  File "C:\Users\pc\Documents\Desarrollo\flask-folders-structure-master\venv\Lib\site-packages\flask\json\provider.py", line 215, in response
    f"{self.dumps(obj, **dump_args)}\n", mimetype=self.mimetype
       ^^^^^^^^^^^^^^^^^^^^^^^^^^^^
  File "C:\Users\pc\Documents\Desarrollo\flask-folders-structure-master\venv\Lib\site-packages\flask\json\provider.py", line 180, in dumps
    return json.dumps(obj, **kwargs)
           ^^^^^^^^^^^^^^^^^^^^^^^^^
  File "C:\Users\pc\AppData\Local\Programs\Python\Python312\Lib\json\__init__.py", line 238, in dumps
    **kw).encode(obj)
          ^^^^^^^^^^^
  File "C:\Users\pc\AppData\Local\Programs\Python\Python312\Lib\json\encoder.py", line 202, in encode
    chunks = list(chunks)
             ^^^^^^^^^^^^
  File "C:\Users\pc\AppData\Local\Programs\Python\Python312\Lib\json\encoder.py", line 439, in _iterencode
    o = _default(o)
        ^^^^^^^^^^^
  File "C:\Users\pc\Documents\Desarrollo\flask-folders-structure-master\venv\Lib\site-packages\flask\json\provider.py", line 120, in _default
    raise TypeError(f"Object of type {type(o).__name__} is not JSON serializable")
TypeError: Object of type User is not JSON serializable

2024-02-02 02:46:41 | ERROR | Object of type Response is not JSON serializable
2024-02-02 02:46:41 | ERROR | Traceback (most recent call last):
  File "C:\Users\pc\Documents\Desarrollo\flask-folders-structure-master\src\routes\UserRoute.py", line 33, in find
    response = jsonify({
               ^^^^^^^^^
  File "C:\Users\pc\Documents\Desarrollo\flask-folders-structure-master\venv\Lib\site-packages\flask\json\__init__.py", line 170, in jsonify
    return current_app.json.response(*args, **kwargs)
           ^^^^^^^^^^^^^^^^^^^^^^^^^^^^^^^^^^^^^^^^^^
  File "C:\Users\pc\Documents\Desarrollo\flask-folders-structure-master\venv\Lib\site-packages\flask\json\provider.py", line 215, in response
    f"{self.dumps(obj, **dump_args)}\n", mimetype=self.mimetype
       ^^^^^^^^^^^^^^^^^^^^^^^^^^^^
  File "C:\Users\pc\Documents\Desarrollo\flask-folders-structure-master\venv\Lib\site-packages\flask\json\provider.py", line 180, in dumps
    return json.dumps(obj, **kwargs)
           ^^^^^^^^^^^^^^^^^^^^^^^^^
  File "C:\Users\pc\AppData\Local\Programs\Python\Python312\Lib\json\__init__.py", line 238, in dumps
    **kw).encode(obj)
          ^^^^^^^^^^^
  File "C:\Users\pc\AppData\Local\Programs\Python\Python312\Lib\json\encoder.py", line 202, in encode
    chunks = list(chunks)
             ^^^^^^^^^^^^
  File "C:\Users\pc\AppData\Local\Programs\Python\Python312\Lib\json\encoder.py", line 432, in _iterencode
    yield from _iterencode_dict(o, _current_indent_level)
  File "C:\Users\pc\AppData\Local\Programs\Python\Python312\Lib\json\encoder.py", line 406, in _iterencode_dict
    yield from chunks
  File "C:\Users\pc\AppData\Local\Programs\Python\Python312\Lib\json\encoder.py", line 439, in _iterencode
    o = _default(o)
        ^^^^^^^^^^^
  File "C:\Users\pc\Documents\Desarrollo\flask-folders-structure-master\venv\Lib\site-packages\flask\json\provider.py", line 120, in _default
    raise TypeError(f"Object of type {type(o).__name__} is not JSON serializable")
TypeError: Object of type Response is not JSON serializable

2024-02-02 13:08:39 | INFO | GET /
2024-02-02 13:08:51 | ERROR | 415 Unsupported Media Type: Did not attempt to load JSON data because the request Content-Type was not 'application/json'.
2024-02-02 13:08:51 | ERROR | Traceback (most recent call last):
  File "/home/joel/Documentos/small_api/src/routes/UserRoute.py", line 20, in find
    id = request.json['id']
  File "/home/joel/Documentos/small_api/venv/lib/python3.10/site-packages/werkzeug/wrappers/request.py", line 565, in json
    return self.get_json()
  File "/home/joel/Documentos/small_api/venv/lib/python3.10/site-packages/werkzeug/wrappers/request.py", line 611, in get_json
    return self.on_json_loading_failed(None)
  File "/home/joel/Documentos/small_api/venv/lib/python3.10/site-packages/flask/wrappers.py", line 130, in on_json_loading_failed
    return super().on_json_loading_failed(e)
  File "/home/joel/Documentos/small_api/venv/lib/python3.10/site-packages/werkzeug/wrappers/request.py", line 654, in on_json_loading_failed
    raise UnsupportedMediaType(
werkzeug.exceptions.UnsupportedMediaType: 415 Unsupported Media Type: Did not attempt to load JSON data because the request Content-Type was not 'application/json'.

2024-02-02 13:10:44 | ERROR | 'id'
2024-02-02 13:10:44 | ERROR | Traceback (most recent call last):
  File "/home/joel/Documentos/small_api/src/routes/UserRoute.py", line 20, in find
    id = request.json['id']
KeyError: 'id'

2024-02-02 13:10:48 | ERROR | (1045, "Access denied for user 'root'@'localhost' (using password: YES)")
2024-02-02 13:10:48 | ERROR | Traceback (most recent call last):
  File "/home/joel/Documentos/small_api/src/database/db_mysql.py", line 12, in get_connection
    return pymysql.connect(
  File "/home/joel/Documentos/small_api/venv/lib/python3.10/site-packages/pymysql/connections.py", line 352, in __init__
    self.connect()
  File "/home/joel/Documentos/small_api/venv/lib/python3.10/site-packages/pymysql/connections.py", line 636, in connect
    self._request_authentication()
  File "/home/joel/Documentos/small_api/venv/lib/python3.10/site-packages/pymysql/connections.py", line 925, in _request_authentication
    auth_packet = self._process_auth(plugin_name, auth_packet)
  File "/home/joel/Documentos/small_api/venv/lib/python3.10/site-packages/pymysql/connections.py", line 1019, in _process_auth
    pkt = self._read_packet()
  File "/home/joel/Documentos/small_api/venv/lib/python3.10/site-packages/pymysql/connections.py", line 729, in _read_packet
    packet.raise_for_error()
  File "/home/joel/Documentos/small_api/venv/lib/python3.10/site-packages/pymysql/protocol.py", line 221, in raise_for_error
    err.raise_mysql_exception(self._data)
  File "/home/joel/Documentos/small_api/venv/lib/python3.10/site-packages/pymysql/err.py", line 143, in raise_mysql_exception
    raise errorclass(errno, errval)
pymysql.err.OperationalError: (1045, "Access denied for user 'root'@'localhost' (using password: YES)")

2024-02-02 13:10:48 | ERROR | 'NoneType' object has no attribute 'cursor'
2024-02-02 13:10:48 | ERROR | Traceback (most recent call last):
  File "/home/joel/Documentos/small_api/src/services/UserService.py", line 32, in save
    with connection.cursor() as cursor:
AttributeError: 'NoneType' object has no attribute 'cursor'

2024-02-02 13:11:35 | ERROR | (1045, "Access denied for user 'root'@'localhost' (using password: YES)")
2024-02-02 13:11:35 | ERROR | Traceback (most recent call last):
  File "/home/joel/Documentos/small_api/src/database/db_mysql.py", line 12, in get_connection
    return pymysql.connect(
  File "/home/joel/Documentos/small_api/venv/lib/python3.10/site-packages/pymysql/connections.py", line 352, in __init__
    self.connect()
  File "/home/joel/Documentos/small_api/venv/lib/python3.10/site-packages/pymysql/connections.py", line 636, in connect
    self._request_authentication()
  File "/home/joel/Documentos/small_api/venv/lib/python3.10/site-packages/pymysql/connections.py", line 925, in _request_authentication
    auth_packet = self._process_auth(plugin_name, auth_packet)
  File "/home/joel/Documentos/small_api/venv/lib/python3.10/site-packages/pymysql/connections.py", line 1019, in _process_auth
    pkt = self._read_packet()
  File "/home/joel/Documentos/small_api/venv/lib/python3.10/site-packages/pymysql/connections.py", line 729, in _read_packet
    packet.raise_for_error()
  File "/home/joel/Documentos/small_api/venv/lib/python3.10/site-packages/pymysql/protocol.py", line 221, in raise_for_error
    err.raise_mysql_exception(self._data)
  File "/home/joel/Documentos/small_api/venv/lib/python3.10/site-packages/pymysql/err.py", line 143, in raise_mysql_exception
    raise errorclass(errno, errval)
pymysql.err.OperationalError: (1045, "Access denied for user 'root'@'localhost' (using password: YES)")

2024-02-02 13:11:35 | ERROR | 'NoneType' object has no attribute 'cursor'
2024-02-02 13:11:35 | ERROR | Traceback (most recent call last):
  File "/home/joel/Documentos/small_api/src/services/UserService.py", line 32, in save
    with connection.cursor() as cursor:
AttributeError: 'NoneType' object has no attribute 'cursor'

2024-02-02 13:11:55 | ERROR | (1045, "Access denied for user 'root'@'localhost' (using password: YES)")
2024-02-02 13:11:55 | ERROR | Traceback (most recent call last):
  File "/home/joel/Documentos/small_api/src/database/db_mysql.py", line 12, in get_connection
    return pymysql.connect(
  File "/home/joel/Documentos/small_api/venv/lib/python3.10/site-packages/pymysql/connections.py", line 352, in __init__
    self.connect()
  File "/home/joel/Documentos/small_api/venv/lib/python3.10/site-packages/pymysql/connections.py", line 636, in connect
    self._request_authentication()
  File "/home/joel/Documentos/small_api/venv/lib/python3.10/site-packages/pymysql/connections.py", line 925, in _request_authentication
    auth_packet = self._process_auth(plugin_name, auth_packet)
  File "/home/joel/Documentos/small_api/venv/lib/python3.10/site-packages/pymysql/connections.py", line 1019, in _process_auth
    pkt = self._read_packet()
  File "/home/joel/Documentos/small_api/venv/lib/python3.10/site-packages/pymysql/connections.py", line 729, in _read_packet
    packet.raise_for_error()
  File "/home/joel/Documentos/small_api/venv/lib/python3.10/site-packages/pymysql/protocol.py", line 221, in raise_for_error
    err.raise_mysql_exception(self._data)
  File "/home/joel/Documentos/small_api/venv/lib/python3.10/site-packages/pymysql/err.py", line 143, in raise_mysql_exception
    raise errorclass(errno, errval)
pymysql.err.OperationalError: (1045, "Access denied for user 'root'@'localhost' (using password: YES)")

2024-02-02 13:11:55 | ERROR | 'NoneType' object has no attribute 'cursor'
2024-02-02 13:11:55 | ERROR | Traceback (most recent call last):
  File "/home/joel/Documentos/small_api/src/services/UserService.py", line 32, in save
    with connection.cursor() as cursor:
AttributeError: 'NoneType' object has no attribute 'cursor'

2024-02-02 13:12:23 | ERROR | (1045, "Access denied for user 'root'@'localhost' (using password: YES)")
2024-02-02 13:12:23 | ERROR | Traceback (most recent call last):
  File "/home/joel/Documentos/small_api/src/database/db_mysql.py", line 12, in get_connection
    return pymysql.connect(
  File "/home/joel/Documentos/small_api/venv/lib/python3.10/site-packages/pymysql/connections.py", line 352, in __init__
    self.connect()
  File "/home/joel/Documentos/small_api/venv/lib/python3.10/site-packages/pymysql/connections.py", line 636, in connect
    self._request_authentication()
  File "/home/joel/Documentos/small_api/venv/lib/python3.10/site-packages/pymysql/connections.py", line 925, in _request_authentication
    auth_packet = self._process_auth(plugin_name, auth_packet)
  File "/home/joel/Documentos/small_api/venv/lib/python3.10/site-packages/pymysql/connections.py", line 1019, in _process_auth
    pkt = self._read_packet()
  File "/home/joel/Documentos/small_api/venv/lib/python3.10/site-packages/pymysql/connections.py", line 729, in _read_packet
    packet.raise_for_error()
  File "/home/joel/Documentos/small_api/venv/lib/python3.10/site-packages/pymysql/protocol.py", line 221, in raise_for_error
    err.raise_mysql_exception(self._data)
  File "/home/joel/Documentos/small_api/venv/lib/python3.10/site-packages/pymysql/err.py", line 143, in raise_mysql_exception
    raise errorclass(errno, errval)
pymysql.err.OperationalError: (1045, "Access denied for user 'root'@'localhost' (using password: YES)")

2024-02-02 13:12:23 | ERROR | 'NoneType' object has no attribute 'cursor'
2024-02-02 13:12:23 | ERROR | Traceback (most recent call last):
  File "/home/joel/Documentos/small_api/src/services/UserService.py", line 32, in save
    with connection.cursor() as cursor:
AttributeError: 'NoneType' object has no attribute 'cursor'

2024-02-02 13:12:43 | ERROR | (1045, "Access denied for user 'root'@'localhost' (using password: YES)")
2024-02-02 13:12:43 | ERROR | Traceback (most recent call last):
  File "/home/joel/Documentos/small_api/src/database/db_mysql.py", line 12, in get_connection
    return pymysql.connect(
  File "/home/joel/Documentos/small_api/venv/lib/python3.10/site-packages/pymysql/connections.py", line 352, in __init__
    self.connect()
  File "/home/joel/Documentos/small_api/venv/lib/python3.10/site-packages/pymysql/connections.py", line 636, in connect
    self._request_authentication()
  File "/home/joel/Documentos/small_api/venv/lib/python3.10/site-packages/pymysql/connections.py", line 925, in _request_authentication
    auth_packet = self._process_auth(plugin_name, auth_packet)
  File "/home/joel/Documentos/small_api/venv/lib/python3.10/site-packages/pymysql/connections.py", line 1019, in _process_auth
    pkt = self._read_packet()
  File "/home/joel/Documentos/small_api/venv/lib/python3.10/site-packages/pymysql/connections.py", line 729, in _read_packet
    packet.raise_for_error()
  File "/home/joel/Documentos/small_api/venv/lib/python3.10/site-packages/pymysql/protocol.py", line 221, in raise_for_error
    err.raise_mysql_exception(self._data)
  File "/home/joel/Documentos/small_api/venv/lib/python3.10/site-packages/pymysql/err.py", line 143, in raise_mysql_exception
    raise errorclass(errno, errval)
pymysql.err.OperationalError: (1045, "Access denied for user 'root'@'localhost' (using password: YES)")

2024-02-02 13:12:43 | ERROR | 'NoneType' object has no attribute 'cursor'
2024-02-02 13:12:43 | ERROR | Traceback (most recent call last):
  File "/home/joel/Documentos/small_api/src/services/UserService.py", line 32, in save
    with connection.cursor() as cursor:
AttributeError: 'NoneType' object has no attribute 'cursor'

2024-02-02 13:13:32 | ERROR | (1045, "Access denied for user 'root'@'localhost' (using password: YES)")
2024-02-02 13:13:32 | ERROR | Traceback (most recent call last):
  File "/home/joel/Documentos/small_api/src/database/db_mysql.py", line 12, in get_connection
    return pymysql.connect(
  File "/home/joel/Documentos/small_api/venv/lib/python3.10/site-packages/pymysql/connections.py", line 352, in __init__
    self.connect()
  File "/home/joel/Documentos/small_api/venv/lib/python3.10/site-packages/pymysql/connections.py", line 636, in connect
    self._request_authentication()
  File "/home/joel/Documentos/small_api/venv/lib/python3.10/site-packages/pymysql/connections.py", line 925, in _request_authentication
    auth_packet = self._process_auth(plugin_name, auth_packet)
  File "/home/joel/Documentos/small_api/venv/lib/python3.10/site-packages/pymysql/connections.py", line 1019, in _process_auth
    pkt = self._read_packet()
  File "/home/joel/Documentos/small_api/venv/lib/python3.10/site-packages/pymysql/connections.py", line 729, in _read_packet
    packet.raise_for_error()
  File "/home/joel/Documentos/small_api/venv/lib/python3.10/site-packages/pymysql/protocol.py", line 221, in raise_for_error
    err.raise_mysql_exception(self._data)
  File "/home/joel/Documentos/small_api/venv/lib/python3.10/site-packages/pymysql/err.py", line 143, in raise_mysql_exception
    raise errorclass(errno, errval)
pymysql.err.OperationalError: (1045, "Access denied for user 'root'@'localhost' (using password: YES)")

2024-02-02 13:15:26 | DEBUG | INSERT INTO `user` (`username`, `password`, `fullname`) VALUES ('User 1', '123', 'full N')
2024-02-02 13:16:13 | DEBUG | INSERT INTO `user` (`username`, `password`, `fullname`) VALUES ('User 1', '123', 'full N')
2024-02-02 14:50:15 | DEBUG | INSERT INTO `user` (`username`, `password`, `fullname`) VALUES ('User 1', '123', 'full N')
2024-02-02 14:50:33 | DEBUG | INSERT INTO `user` (`username`, `password`, `fullname`) VALUES ('User 1', '123', 'full N')
2024-02-02 14:51:44 | DEBUG | INSERT INTO `user` (`username`, `password`, `fullname`) VALUES ('User 1', '123', 'full N')
2024-02-02 14:55:49 | DEBUG | INSERT INTO `user` (`username`, `password`, `fullname`) VALUES ('User 1', '123', 'full N')
2024-02-02 16:53:22 | DEBUG | INSERT INTO `user` (`username`, `password`, `fullname`) VALUES ('User 1', '123', 'full N')
